Workbook

Sheet Dashboard
A1: AR DELINQUENT REPORT - SUMMARY DASHBOARD
A2: Valley Ranch Master
A3: Report Date: 4/17/2026 (Posted Date: 3/31/2026)
A5: KEY METRICS
A6: Total Delinquent Accounts | C6: =COUNTA('AR Delinquent Report'!A2:A536) -> 535
A7: Total Outstanding Balance | C7: =SUM('AR Delinquent Report'!J2:J536) -> 1636571.2
A8: Average Balance per Account | C8: =AVERAGE('AR Delinquent Report'!J2:J536) -> 3059.0116
A9: Highest Balance | C9: =MAX('AR Delinquent Report'!J2:J536) -> 311462.29
A10: Accounts Over $10,000 | C10: =COUNTIF('AR Delinquent Report'!J2:J536,">10000") -> 29
A11: Accounts Over $1,000 | C11: =COUNTIF('AR Delinquent Report'!J2:J536,">1000") -> 183
A13: AGING BUCKET SUMMARY
A14: Aging Bucket | B14: Total Amount | C14: # of Accounts | D14: % of Total $ | E14: Avg per Account
A15: Current | B15: =SUM('AR Delinquent Report'!C2:C536) -> 104667.02 | C15: =COUNTIF('AR Delinquent Report'!C2:C536,">0") -> 400 | D15: =B15/$C$7 -> 0.063955067 | E15: =IF(C15>0,B15/C15,0) -> 261.66755
A16: 30-59 Days | B16: =SUM('AR Delinquent Report'!D2:D536) -> 45484.11 | C16: =COUNTIF('AR Delinquent Report'!D2:D536,">0") -> 44 | D16: =B16/$C$7 -> 0.02779232 | E16: =IF(C16>0,B16/C16,0) -> 1033.7298
A17: 60-89 Days | B17: =SUM('AR Delinquent Report'!E2:E536) -> 885580.86 | C17: =COUNTIF('AR Delinquent Report'!E2:E536,">0") -> 378 | D17: =B17/$C$7 -> 0.54111967 | E17: =IF(C17>0,B17/C17,0) -> 2342.8065
A18: 90 Days | B18: =SUM('AR Delinquent Report'!F2:F536) -> 21988.96 | C18: =COUNTIF('AR Delinquent Report'!F2:F536,">0") -> 59 | D18: =B18/$C$7 -> 0.013435994 | E18: =IF(C18>0,B18/C18,0) -> 372.69424
A19: 120 Days | B19: =SUM('AR Delinquent Report'!G2:G536) -> 34769.77 | C19: =COUNTIF('AR Delinquent Report'!G2:G536,">0") -> 69 | D19: =B19/$C$7 -> 0.021245498 | E19: =IF(C19>0,B19/C19,0) -> 503.90971
A20: 150 Days | B20: =SUM('AR Delinquent Report'!H2:H536) -> 162022.4 | C20: =COUNTIF('AR Delinquent Report'!H2:H536,">0") -> 59 | D20: =B20/$C$7 -> 0.099001132 | E20: =IF(C20>0,B20/C20,0) -> 2746.1424
A21: >180 Days | B21: =SUM('AR Delinquent Report'!I2:I536) -> 382058.06 | C21: =COUNTIF('AR Delinquent Report'!I2:I536,">0") -> 192 | D21: =B21/$C$7 -> 0.23345032 | E21: =IF(C21>0,B21/C21,0) -> 1989.8857
A22: TOTAL | B22: =SUM(B15:B21) -> 1636571.2 | C22: =C6 -> 535 | D22: =SUM(D15:D21) -> 1 | E22: =IF(C22>0,B22/C22,0) -> 3059.0116
A24: SUMMARY BY COLLECTION STAGE
A25: Collection Stage | B25: # Accounts | C25: Total Balance | D25: % of Total | E25: Avg Balance
A26: Attny | B26: =COUNTIF('AR Delinquent Report'!B2:B536,"Attny") -> 63 | C26: =SUMIF('AR Delinquent Report'!B2:B536,"Attny",'AR Delinquent Report'!J2:J536) -> 718096.47 | D26: =IF($C$7>0,C26/$C$7,0) -> 0.43878108 | E26: =IF(B26>0,C26/B26,0) -> 11398.357
A27: Attny Bankruptcy | B27: =COUNTIF('AR Delinquent Report'!B2:B536,"Attny Bankruptcy") -> 1 | C27: =SUMIF('AR Delinquent Report'!B2:B536,"Attny Bankruptcy",'AR Delinquent Report'!J2:J536) -> 759.67 | D27: =IF($C$7>0,C27/$C$7,0) -> 0.0004641839 | E27: =IF(B27>0,C27/B27,0) -> 759.67
A28: Bankruptcy | B28: =COUNTIF('AR Delinquent Report'!B2:B536,"Bankruptcy") -> 1 | C28: =SUMIF('AR Delinquent Report'!B2:B536,"Bankruptcy",'AR Delinquent Report'!J2:J536) -> 595 | D28: =IF($C$7>0,C28/$C$7,0) -> 0.000363565 | E28: =IF(B28>0,C28/B28,0) -> 595
A29: Demand Lien Notice | B29: =COUNTIF('AR Delinquent Report'!B2:B536,"Demand Lien Notice") -> 201 | C29: =SUMIF('AR Delinquent Report'!B2:B536,"Demand Lien Notice",'AR Delinquent Report'!J2:J536) -> 617349.29 | D29: =IF($C$7>0,C29/$C$7,0) -> 0.37722117 | E29: =IF(B29>0,C29/B29,0) -> 3071.3895
A30: Initial Late Letter | B30: =COUNTIF('AR Delinquent Report'!B2:B536,"Initial Late Letter") -> 7 | C30: =SUMIF('AR Delinquent Report'!B2:B536,"Initial Late Letter",'AR Delinquent Report'!J2:J536) -> 57359.96 | D30: =IF($C$7>0,C30/$C$7,0) -> 0.035048864 | E30: =IF(B30>0,C30/B30,0) -> 8194.28
A31: Payment Plan | B31: =COUNTIF('AR Delinquent Report'!B2:B536,"Payment Plan") -> 6 | C31: =SUMIF('AR Delinquent Report'!B2:B536,"Payment Plan",'AR Delinquent Report'!J2:J536) -> 4006.27 | D31: =IF($C$7>0,C31/$C$7,0) -> 0.0024479656 | E31: =IF(B31>0,C31/B31,0) -> 667.71167
A32: Pending Board | B32: =COUNTIF('AR Delinquent Report'!B2:B536,"Pending Board") -> 2 | C32: =SUMIF('AR Delinquent Report'!B2:B536,"Pending Board",'AR Delinquent Report'!J2:J536) -> 3966.17 | D32: =IF($C$7>0,C32/$C$7,0) -> 0.0024234632 | E32: =IF(B32>0,C32/B32,0) -> 1983.085
A33: Pre-Bankruptcy | B33: =COUNTIF('AR Delinquent Report'!B2:B536,"Pre-Bankruptcy") -> 1 | C33: =SUMIF('AR Delinquent Report'!B2:B536,"Pre-Bankruptcy",'AR Delinquent Report'!J2:J536) -> 916.95 | D33: =IF($C$7>0,C33/$C$7,0) -> 0.00056028727 | E33: =IF(B33>0,C33/B33,0) -> 916.95
A34: Pre-Bankruptcy Attny | B34: =COUNTIF('AR Delinquent Report'!B2:B536,"Pre-Bankruptcy Attny") -> 2 | C34: =SUMIF('AR Delinquent Report'!B2:B536,"Pre-Bankruptcy Attny",'AR Delinquent Report'!J2:J536) -> 25103.31 | D34: =IF($C$7>0,C34/$C$7,0) -> 0.015338966 | E34: =IF(B34>0,C34/B34,0) -> 12551.655
A35: Pre-Bankruptcy Bankruptcy | B35: =COUNTIF('AR Delinquent Report'!B2:B536,"Pre-Bankruptcy Bankruptcy") -> 1 | C35: =SUMIF('AR Delinquent Report'!B2:B536,"Pre-Bankruptcy Bankruptcy",'AR Delinquent Report'!J2:J536) -> 3536.56 | D35: =IF($C$7>0,C35/$C$7,0) -> 0.002160957 | E35: =IF(B35>0,C35/B35,0) -> 3536.56
A36: (No Stage Assigned) | B36: =COUNTIF('AR Delinquent Report'!B2:B536,"") -> 250 | C36: =SUMIF('AR Delinquent Report'!B2:B536,"",'AR Delinquent Report'!J2:J536) -> 204881.53 | D36: =IF($C$7>0,C36/$C$7,0) -> 0.1251895 | E36: =IF(B36>0,C36/B36,0) -> 819.52612
A37: TOTAL | B37: =SUM(B26:B36) -> 535 | C37: =SUM(C26:C36) -> 1636571.2 | D37: =SUM(D26:D36) -> 1 | E37: =IF(B37>0,C37/B37,0) -> 3059.0116
A39: TOP 10 HIGH PRIORITY ACCOUNTS (by Total Balance)
A40: Rank | B40: Acct # | C40: Collection Stage | D40: Balance
A41: 1 | B41: =INDEX('AR Delinquent Report'!A2:A536,MATCH(LARGE('AR Delinquent Report'!J2:J536,1),'AR Delinquent Report'!J2:J536,0)) -> 851983 | C41: =INDEX('AR Delinquent Report'!B2:B536,MATCH(LARGE('AR Delinquent Report'!J2:J536,1),'AR Delinquent Report'!J2:J536,0)) -> Attny | D41: =LARGE('AR Delinquent Report'!J2:J536,1) -> 311462.29
A42: 2 | B42: =INDEX('AR Delinquent Report'!A2:A536,MATCH(LARGE('AR Delinquent Report'!J2:J536,2),'AR Delinquent Report'!J2:J536,0)) -> 489515 | C42: =INDEX('AR Delinquent Report'!B2:B536,MATCH(LARGE('AR Delinquent Report'!J2:J536,2),'AR Delinquent Report'!J2:J536,0)) -> Demand Lien Notice | D42: =LARGE('AR Delinquent Report'!J2:J536,2) -> 118512.5
A43: 3 | B43: =INDEX('AR Delinquent Report'!A2:A536,MATCH(LARGE('AR Delinquent Report'!J2:J536,3),'AR Delinquent Report'!J2:J536,0)) -> 474628 | C43: =INDEX('AR Delinquent Report'!B2:B536,MATCH(LARGE('AR Delinquent Report'!J2:J536,3),'AR Delinquent Report'!J2:J536,0)) -> Demand Lien Notice | D43: =LARGE('AR Delinquent Report'!J2:J536,3) -> 79328.75
A44: 4 | B44: =INDEX('AR Delinquent Report'!A2:A536,MATCH(LARGE('AR Delinquent Report'!J2:J536,4),'AR Delinquent Report'!J2:J536,0)) -> 866536 | C44: =INDEX('AR Delinquent Report'!B2:B536,MATCH(LARGE('AR Delinquent Report'!J2:J536,4),'AR Delinquent Report'!J2:J536,0)) -> Demand Lien Notice | D44: =LARGE('AR Delinquent Report'!J2:J536,4) -> 65411.73
...

Sheet AR Delinquent Report
A1: Acct # | B1: Status | C1: Current | D1: 30-59 Days | E1: 60-89 Days | F1: 90 Days | G1: 120 Days | H1: 150 Days | I1: >180 Days | J1: Balance | K1: Section
A2: 851983 | B2: Attny | C2: 0 | D2: 0 | E2: 142223.9 | F2: 2864.12 | G2: 7999.27 | H2: 158375 | I2: 0 | J2: 311462.29 | K2: Master
A3: 489515 | B3: Demand Lien Notice | C3: 1512.5 | D3: 0 | E3: 117000 | F3: 0 | G3: 0 | H3: 0 | I3: 0 | J3: 118512.5 | K3: Master
A4: 474628 | B4: Demand Lien Notice | C4: 1028.75 | D4: 0 | E4: 78300 | F4: 0 | G4: 0 | H4: 0 | I4: 0 | J4: 79328.75 | K4: Master
A5: 866536 | B5: Demand Lien Notice | C5: 851.38 | D5: 0 | E5: 64560.35 | F5: 0 | G5: 0 | H5: 0 | I5: 0 | J5: 65411.73 | K5: Master
A6: 474633 | B6: Initial Late Letter | C6: 0 | D6: 0 | E6: 50400 | F6: 0 | G6: 500 | H6: 0 | I6: 2660 | J6: 53560 | K6: Master
A7: 866525 | B7: Demand Lien Notice | C7: 623.75 | D7: 0 | E7: 46350 | F7: 0 | G7: 0 | H7: 0 | I7: 0 | J7: 46973.75 | K7: Master
A8: 474637 | B8: Demand Lien Notice | C8: 563.68 | D8: 0 | E8: 41094 | F8: 0 | G8: 0 | H8: 0 | I8: 0 | J8: 41657.68 | K8: Master
A9: 475630 | C9: 3012.5 | D9: 6399 | E9: 1550 | F9: 0 | G9: 0 | H9: 0 | I9: 18249.01 | J9: 29210.51 | K9: Master
A10: 474631 | B10: Demand Lien Notice | C10: 376.25 | D10: 0 | E10: 26100 | F10: 0 | G10: 0 | H10: 0 | I10: 0 | J10: 26476.25 | K10: Master
A11: 475816 | B11: Attny | C11: 3753.64 | D11: 6100 | E11: 2376.85 | F11: 70.17 | G11: 70.17 | H11: 70.17 | I11: 11937.07 | J11: 24378.07 | K11: Master
A12: 475151 | B12: Demand Lien Notice | C12: 0 | D12: 25 | E12: 1164.18 | F12: 0 | G12: 92.5 | H12: 0 | I12: 17907.07 | J12: 19188.75 | K12: Master
A13: 478678 | B13: Attny | C13: 1230.75 | D13: 0 | E13: 1601.19 | F13: 136.01 | G13: 1452.53 | H13: 136.01 | I13: 13435.99 | J13: 17992.48 | K13: Master
A14: 475726 | B14: Pre-Bankruptcy Attny | C14: 0 | D14: 0 | E14: 0 | F14: 0 | G14: 0 | H14: 0 | I14: 16897.54 | J14: 16897.54 | K14: Master
A15: 476849 | B15: Attny | C15: 549.26 | D15: 0 | E15: 0 | F15: 14574.15 | G15: 62.5 | H15: 0 | I15: 0 | J15: 15185.91 | K15: Master
A16: 477923 | C16: 0 | D16: 0 | E16: 0 | F16: 0 | G16: 0 | H16: 0 | I16: 15136.52 | J16: 15136.52 | K16: Master
A17: 474495 | B17: Attny | C17: 1178.53 | D17: 0 | E17: 1128.03 | F17: 88.45 | G17: 88.45 | H17: 88.45 | I17: 12456.71 | J17: 15028.62 | K17: Master
A18: 475248 | B18: Attny | C18: 142.19 | D18: 0 | E18: 655.3 | F18: 73.41 | G18: 2013.46 | H18: 73.41 | I18: 10920.56 | J18: 13878.33 | K18: Master
A19: 478639 | B19: Attny | C19: 1222.64 | D19: 410 | E19: 1098.93 | F19: 69.6 | G19: 674.6 | H19: 69.6 | I19: 8516.16 | J19: 12061.53 | K19: Master
A20: 477403 | B20: Attny | C20: 88.89 | D20: 0 | E20: 1058.89 | F20: 77.74 | G20: 77.74 | H20: 77.74 | I20: 10501.11 | J20: 11882.11 | K20: Master
A21: 475404 | B21: Attny | C21: 2145.21 | D21: 0 | E21: 111.46 | F21: 51.57 | G21: 861.15 | H21: 51.57 | I21: 8590.42 | J21: 11811.38 | K21: Master
A22: 476445 | B22: Attny | C22: 1286.88 | D22: 230 | E22: 904.31 | F22: 66.53 | G22: 801.62 | H22: 66.53 | I22: 8319.46 | J22: 11675.33 | K22: Master
A23: 673358 | B23: Attny | C23: 0 | D23: 233.75 | E23: 2504.93 | F23: 68.63 | G23: 640.5 | H23: 68.63 | I23: 7539.02 | J23: 11055.46 | K23: Master
A24: 476688 | B24: Attny | C24: 1243.15 | D24: 39.82 | E24: 1237.88 | F24: 53.35 | G24: 413.35 | H24: 53.35 | I24: 7960.53 | J24: 11001.43 | K24: Master
A25: 474466 | B25: Attny | C25: 354.33 | D25: 0 | E25: 748.65 | F25: 53.92 | G25: 151.42 | H25: 53.92 | I25: 9404.08 | J25: 10766.32 | K25: Master
A26: 478075 | C26: 2950 | D26: 6100 | E26: 1600 | F26: 0 | G26: 0 | H26: 0 | I26: 0 | J26: 10650 | K26: Unbillable
A27: 478431 | C27: 2998.75 | D27: 6100 | E27: 1550 | F27: 0 | G27: 0 | H27: 0 | I27: 0 | J27: 10648.75 | K27: Master
A28: 477701 | B28: Attny | C28: 99.39 | D28: 0 | E28: 1322.49 | F28: 59.54 | G28: 0 | H28: 63.33 | I28: 9038.42 | J28: 10583.17 | K28: Master
A29: 477963 | B29: Demand Lien Notice | C29: 3075.11 | D29: 4871.75 | E29: 2558.86 | F29: 0 | G29: 0 | H29: 0 | I29: 50 | J29: 10555.72 | K29: Master
A30: 475721 | B30: Attny | C30: 1375.48 | D30: 48.75 | E30: 840.36 | F30: 65.9 | G30: 147.15 | H30: 65.9 | I30: 8002.44 | J30: 10545.98 | K30: Master
A31: 477413 | B31: Attny | C31: 0 | D31: 0 | E31: 140.43 | F31: 0 | G31: 180 | H31: 0 | I31: 9547.64 | J31: 9868.07 | K31: Master
A32: 475316 | B32: Attny | C32: 76.91 | D32: 0 | E32: 750.81 | F32: 69.35 | G32: 530.6 | H32: 69.35 | I32: 8232.15 | J32: 9729.17 | K32: Master
A33: 476452 | B33: Attny | C33: 1282.4 | D33: 0 | E33: 997.68 | F33: 68.44 | G33: 68.44 | H33: 68.44 | I33: 6445.64 | J33: 8931.04 | K33: Master
A34: 478410 | B34: Attny | C34: 2950 | D34: 3050 | E34: 2769.33 | F34: 0 | G34: 0 | H34: 0 | I34: 66.63 | J34: 8835.96 | K34: Master
A35: 579928 | B35: Demand Lien Notice | C35: 3056.44 | D35: 3251 | E35: 2164.89 | F35: 0 | G35: 0 | H35: 0 | I35: 0 | J35: 8472.33 | K35: Master
A36: 764438 | B36: Attny | C36: 2130.44 | D36: 106.25 | E36: 1002.82 | F36: 70.64 | G36: 1021.89 | H36: 70.64 | I36: 3936.84 | J36: 8339.52 | K36: Master
A37: 478718 | C37: 0 | D37: 0 | E37: 864.98 | F37: 60.06 | G37: 60.06 | H37: 60.06 | I37: 7175.47 | J37: 8220.63 | K37: Master
A38: 474966 | B38: Pre-Bankruptcy Attny | C38: 0 | D38: 0 | E38: 0 | F38: 0 | G38: 790.96 | H38: 30 | I38: 7384.81 | J38: 8205.77 | K38: Master
A39: 476119 | B39: Attny | C39: 491.56 | D39: 0 | E39: 894.4 | F39: 0 | G39: 1114.14 | H39: 57.93 | I39: 5559.16 | J39: 8117.19 | K39: Master
A40: 476708 | B40: Attny | C40: 951.22 | D40: 97.5 | E40: 1133.74 | F40: 73.54 | G40: 228.54 | H40: 73.54 | I40: 5225.04 | J40: 7783.12 | K40: Master
...
